Traceback (most recent call last):
  File "E:/tensor/pytest/pytest/dataStructure/10exception.py", line 49, in saveTheExceptionInfoIntoAFile
    raise Exception(' This is the error message.')
Exception:  This is the error message.
