Traceback (most recent call last):
  File "E:/tensor/pytest/pytest/dataStructure/organizeFile.py", line 48, in saveTheExceptionTracebackInfoIntoAFile
    raise Exception('This is the error message.')
Exception: This is the error message.
